2025-06-03 15:44:04,543 INFO    MainThread:25004 [wandb_setup.py:_flush():70] Current SDK version is 0.19.11
2025-06-03 15:44:04,544 INFO    MainThread:25004 [wandb_setup.py:_flush():70] Configure stats pid to 25004
2025-06-03 15:44:04,544 INFO    MainThread:25004 [wandb_setup.py:_flush():70] Loading settings from C:\Users\LiChangHao\.config\wandb\settings
2025-06-03 15:44:04,544 INFO    MainThread:25004 [wandb_setup.py:_flush():70] Loading settings from E:\Learning_Documents\Computer_Vision_and_Intelligent_Medical_Image_Analysis\BIG_HOMEWORK\LVIT-main\wandb\settings
2025-06-03 15:44:04,544 INFO    MainThread:25004 [wandb_setup.py:_flush():70] Loading settings from environment variables
2025-06-03 15:44:04,545 INFO    MainThread:25004 [wandb_init.py:setup_run_log_directory():724] Logging user logs to E:\Learning_Documents\Computer_Vision_and_Intelligent_Medical_Image_Analysis\BIG_HOMEWORK\LVIT-main\wandb\run-20250603_154404-cbjjahsq\logs\debug.log
2025-06-03 15:44:04,545 INFO    MainThread:25004 [wandb_init.py:setup_run_log_directory():725] Logging internal logs to E:\Learning_Documents\Computer_Vision_and_Intelligent_Medical_Image_Analysis\BIG_HOMEWORK\LVIT-main\wandb\run-20250603_154404-cbjjahsq\logs\debug-internal.log
2025-06-03 15:44:04,546 INFO    MainThread:25004 [wandb_init.py:init():852] calling init triggers
2025-06-03 15:44:04,546 INFO    MainThread:25004 [wandb_init.py:init():857] wandb.init called with sweep_config: {}
config: {'learning_rate': 0.001, 'batch_size': 2, 'epochs': 2000, 'model': 'LViT', 'task': 'MosMedDataPlus', '_wandb': {}}
2025-06-03 15:44:04,546 INFO    MainThread:25004 [wandb_init.py:init():893] starting backend
2025-06-03 15:44:04,546 INFO    MainThread:25004 [wandb_init.py:init():897] sending inform_init request
2025-06-03 15:44:04,594 INFO    MainThread:25004 [backend.py:_multiprocessing_setup():101] multiprocessing start_methods=spawn, using: spawn
2025-06-03 15:44:04,595 INFO    MainThread:25004 [wandb_init.py:init():907] backend started and connected
2025-06-03 15:44:04,596 INFO    MainThread:25004 [wandb_init.py:init():1005] updated telemetry
2025-06-03 15:44:04,661 INFO    MainThread:25004 [wandb_init.py:init():1029] communicating run to backend with 90.0 second timeout
2025-06-03 15:44:05,672 WARNING MainThread:25004 [wandb_init.py:init():1681] [no run ID] interrupted
Traceback (most recent call last):
  File "E:\anaconda\envs\LViT_env\lib\site-packages\wandb\sdk\wandb_init.py", line 1677, in init
    return wi.init(run_settings, run_config, run_printer)
  File "E:\anaconda\envs\LViT_env\lib\site-packages\wandb\sdk\wandb_init.py", line 1055, in init
    result = wait_with_progress(
  File "E:\anaconda\envs\LViT_env\lib\site-packages\wandb\sdk\mailbox\wait_with_progress.py", line 24, in wait_with_progress
    return wait_all_with_progress(
  File "E:\anaconda\envs\LViT_env\lib\site-packages\wandb\sdk\mailbox\wait_with_progress.py", line 70, in wait_all_with_progress
    return _wait_handles(handle_list, timeout=progress_after)
  File "E:\anaconda\envs\LViT_env\lib\site-packages\wandb\sdk\mailbox\wait_with_progress.py", line 110, in _wait_handles
    results.append(handle.wait_or(timeout=remaining_timeout))
  File "E:\anaconda\envs\LViT_env\lib\site-packages\wandb\sdk\mailbox\mailbox_handle.py", line 122, in wait_or
    return self._fn(self._handle.wait_or(timeout=timeout))
  File "E:\anaconda\envs\LViT_env\lib\site-packages\wandb\sdk\mailbox\response_handle.py", line 88, in wait_or
    if not self._event.wait(timeout=timeout):
  File "E:\anaconda\envs\LViT_env\lib\threading.py", line 581, in wait
    signaled = self._cond.wait(timeout)
  File "E:\anaconda\envs\LViT_env\lib\threading.py", line 316, in wait
    gotit = waiter.acquire(True, timeout)
KeyboardInterrupt
2025-06-03 15:44:06,638 INFO    MsgRouterThr:25004 [mailbox.py:close():129] [no run ID] Closing mailbox, abandoning 1 handles.
2025-06-03 15:44:19,610 INFO    Thread-10 :25004 [retry.py:__call__():175] [no run ID] Retry attempt failed:
Traceback (most recent call last):
  File "E:\anaconda\envs\LViT_env\lib\site-packages\urllib3\connection.py", line 198, in _new_conn
    sock = connection.create_connection(
  File "E:\anaconda\envs\LViT_env\lib\site-packages\urllib3\util\connection.py", line 85, in create_connection
    raise err
  File "E:\anaconda\envs\LViT_env\lib\site-packages\urllib3\util\connection.py", line 73, in create_connection
    sock.connect(sa)
socket.timeout: timed out

The above exception was the direct cause of the following exception:

Traceback (most recent call last):
  File "E:\anaconda\envs\LViT_env\lib\site-packages\urllib3\connectionpool.py", line 787, in urlopen
    response = self._make_request(
  File "E:\anaconda\envs\LViT_env\lib\site-packages\urllib3\connectionpool.py", line 488, in _make_request
    raise new_e
  File "E:\anaconda\envs\LViT_env\lib\site-packages\urllib3\connectionpool.py", line 464, in _make_request
    self._validate_conn(conn)
  File "E:\anaconda\envs\LViT_env\lib\site-packages\urllib3\connectionpool.py", line 1093, in _validate_conn
    conn.connect()
  File "E:\anaconda\envs\LViT_env\lib\site-packages\urllib3\connection.py", line 704, in connect
    self.sock = sock = self._new_conn()
  File "E:\anaconda\envs\LViT_env\lib\site-packages\urllib3\connection.py", line 207, in _new_conn
    raise ConnectTimeoutError(
urllib3.exceptions.ConnectTimeoutError: (<urllib3.connection.HTTPSConnection object at 0x0000027E3840FEB0>, 'Connection to api.wandb.ai timed out. (connect timeout=20)')

The above exception was the direct cause of the following exception:

Traceback (most recent call last):
  File "E:\anaconda\envs\LViT_env\lib\site-packages\requests\adapters.py", line 667, in send
    resp = conn.urlopen(
  File "E:\anaconda\envs\LViT_env\lib\site-packages\urllib3\connectionpool.py", line 841, in urlopen
    retries = retries.increment(
  File "E:\anaconda\envs\LViT_env\lib\site-packages\urllib3\util\retry.py", line 519, in increment
    raise MaxRetryError(_pool, url, reason) from reason  # type: ignore[arg-type]
urllib3.exceptions.MaxRetryError: HTTPSConnectionPool(host='api.wandb.ai', port=443): Max retries exceeded with url: /graphql (Caused by ConnectTimeoutError(<urllib3.connection.HTTPSConnection object at 0x0000027E3840FEB0>, 'Connection to api.wandb.ai timed out. (connect timeout=20)'))

During handling of the above exception, another exception occurred:

Traceback (most recent call last):
  File "E:\anaconda\envs\LViT_env\lib\site-packages\wandb\sdk\lib\retry.py", line 134, in __call__
    result = self._call_fn(*args, **kwargs)
  File "E:\anaconda\envs\LViT_env\lib\site-packages\wandb\sdk\internal\internal_api.py", line 398, in execute
    return self.client.execute(*args, **kwargs)  # type: ignore
  File "E:\anaconda\envs\LViT_env\lib\site-packages\wandb\vendor\gql-0.2.0\wandb_gql\client.py", line 52, in execute
    result = self._get_result(document, *args, **kwargs)
  File "E:\anaconda\envs\LViT_env\lib\site-packages\wandb\vendor\gql-0.2.0\wandb_gql\client.py", line 60, in _get_result
    return self.transport.execute(document, *args, **kwargs)
  File "E:\anaconda\envs\LViT_env\lib\site-packages\wandb\sdk\lib\gql_request.py", line 58, in execute
    request = self.session.post(self.url, **post_args)
  File "E:\anaconda\envs\LViT_env\lib\site-packages\requests\sessions.py", line 637, in post
    return self.request("POST", url, data=data, json=json, **kwargs)
  File "E:\anaconda\envs\LViT_env\lib\site-packages\requests\sessions.py", line 589, in request
    resp = self.send(prep, **send_kwargs)
  File "E:\anaconda\envs\LViT_env\lib\site-packages\requests\sessions.py", line 703, in send
    r = adapter.send(request, **kwargs)
  File "E:\anaconda\envs\LViT_env\lib\site-packages\requests\adapters.py", line 688, in send
    raise ConnectTimeout(e, request=request)
requests.exceptions.ConnectTimeout: HTTPSConnectionPool(host='api.wandb.ai', port=443): Max retries exceeded with url: /graphql (Caused by ConnectTimeoutError(<urllib3.connection.HTTPSConnection object at 0x0000027E3840FEB0>, 'Connection to api.wandb.ai timed out. (connect timeout=20)'))
